Workbook

Sheet Bugs
A1: FutureNow Ticket | B1: ID | C1: Recurrent Issue (tech) | D1: Recurrent Issue (Business)
A2: INC42077895 | B2: 6000128546
B3: 6000139374
A4: INC42788004 | B4: 6000140063
A5: INC42930584 | B5: 6000142441
A6: INC42930203 | B6: 6000142434
B7: 6000142896
A8: INC43019830 | D8: x
A9: INC43035790
A10: INC43117032
A11: INC43149903
A12: INC43163860 | D12: x
A13: INC43215416 | D13: x
A14: INC43249416 | D14: x
A15: INC43255046 | D15: x
A16: INC43259250 | D16: x
A17: INC43287075 | B17: 6000147166
A18: INC43302173 | D18: x
A19: INC43332346
A20: INC43334219 | D20: x
A21: INC43344804 | D21: x
A22: INC43356074
A23: INC43371571
A24: INC43399228 | B24: 6000147888
A25: INC43400197 | B25: 6000147912
A26: INC43433151
A27: INC43436495
A28: INC43465907
A29: INC43469397 | D29: x
A30: INC43469550 | D30: x
A31: INC43487284 | D31: x
A32: INC43498557
A33: INC43504801
A34: INC43508169
A35: INC43508280 | D35: x
A36: INC43508305 | D36: x
A37: INC43508194
A38: INC43508341 | D38: x
A39: INC43512839 | B39: 6000149049
A40: INC43503029
...

Sheet MasterData
B2: Open Status | C2: Transitional Status | D2: Closed Status | F2: Priority | I2: Starts | J2: Ends
B3: In Process | C3: Defect Correction in Process | D3: Closed | F3: *1* | H3: CW24 | I3: 45817 | J3: 45823
B4: Forwarded | C4: Proposed Solution | D4: Confirm_Closed | F4: *2* | H4: CW25 | I4: 45824 | J4: 45830
B5: Customer Action | C5: Solution Proposed | D5: Confirmed | F5: *3* | H5: CW26 | I5: 45831 | J5: 45837
B6: not in Scope | D6: Resolved | F6: *4* | H6: CW27 | I6: 45838 | J6: 45844
B7: Postponed | D7: Closed | H7: CW28 | I7: 45845 | J7: 45851
B8: In Progress | H8: CW29 | I8: 45852 | J8: 45858
B9: Pending | H9: CW30 | I9: 45859 | J9: 45865
H10: CW31 | I10: 45866 | J10: 45872
H11: CW32 | I11: 45873 | J11: 45879
H12: CW33 | I12: 45880 | J12: 45886
H13: CW34 | I13: 45887 | J13: 45893
H14: CW35 | I14: 45894 | J14: 45900
H15: CW36 | I15: 45901 | J15: 45907
H16: CW37 | I16: 45908 | J16: 45914
H17: CW38 | I17: 45915 | J17: 45921
H18: CW39 | I18: 45922 | J18: 45928
H19: CW40 | I19: 45929 | J19: 45935
B20: System Users | H20: CW41 | I20: 45936 | J20: 45942
B21: SAP SOLUTION MANAGER S1A | H21: CW42 | I21: 45943 | J21: 45949
H22: CW43 | I22: 45950 | J22: 45956
H23: CW44 | I23: 45957 | J23: 45963
H24: CW45 | I24: 45964 | J24: 45970
H25: CW46 | I25: 45971 | J25: 45977
H26: CW47 | I26: 45978 | J26: 45984
H27: CW48 | I27: 45985 | J27: 45991
H28: CW49 | I28: 45992 | J28: 45998
H29: CW50 | I29: 45999 | J29: 46005
H30: CW51 | I30: 46006 | J30: 46012
H31: CW52 | I31: 46013 | J31: 46019
H32: CW53 | I32: 46020 | J32: 46026

Sheet Comparator
A1: =IF('VIM-Incidents_20250724'!A1<>'VIM-Incidents_20250731'!A1,"Difference","OK") -> OK | B1: =IF('VIM-Incidents_20250724'!B1<>'VIM-Incidents_20250731'!B1,"Difference","OK") -> OK | C1: =IF('VIM-Incidents_20250724'!C1<>'VIM-Incidents_20250731'!C1,"Difference","OK") -> OK | D1: =IF('VIM-Incidents_20250724'!D1<>'VIM-Incidents_20250731'!D1,"Difference","OK") -> OK | E1: =IF('VIM-Incidents_20250724'!E1<>'VIM-Incidents_20250731'!E1,"Difference","OK") -> OK | F1: =IF('VIM-Incidents_20250724'!F1<>'VIM-Incidents_20250731'!F1,"Difference","OK") -> OK | G1: =IF('VIM-Incidents_20250724'!G1<>'VIM-Incidents_20250731'!G1,"Difference","OK") -> OK | H1: =IF('VIM-Incidents_20250724'!H1<>'VIM-Incidents_20250731'!H1,"Difference","OK") -> OK | ... S1: =IF('VIM-Incidents_20250724'!S1<>'VIM-Incidents_20250731'!S1,"Difference","OK") -> OK
A2: =IF('VIM-Incidents_20250724'!A2<>'VIM-Incidents_20250731'!A2,"Difference","OK") -> OK | B2: =IF('VIM-Incidents_20250724'!B2<>'VIM-Incidents_20250731'!B2,"Difference","OK") -> OK | C2: =IF('VIM-Incidents_20250724'!C2<>'VIM-Incidents_20250731'!C2,"Difference","OK") -> OK | D2: =IF('VIM-Incidents_20250724'!D2<>'VIM-Incidents_20250731'!D2,"Difference","OK") -> OK | E2: =IF('VIM-Incidents_20250724'!E2<>'VIM-Incidents_20250731'!E2,"Difference","OK") -> OK | F2: =IF('VIM-Incidents_20250724'!F2<>'VIM-Incidents_20250731'!F2,"Difference","OK") -> OK | G2: =IF('VIM-Incidents_20250724'!G2<>'VIM-Incidents_20250731'!G2,"Difference","OK") -> OK | H2: =IF('VIM-Incidents_20250724'!H2<>'VIM-Incidents_20250731'!H2,"Difference","OK") -> OK | ... S2: =IF('VIM-Incidents_20250724'!S2<>'VIM-Incidents_20250731'!S2,"Difference","OK") -> OK
A3: =IF('VIM-Incidents_20250724'!A3<>'VIM-Incidents_20250731'!A3,"Difference","OK") -> OK | B3: =IF('VIM-Incidents_20250724'!B3<>'VIM-Incidents_20250731'!B3,"Difference","OK") -> OK | C3: =IF('VIM-Incidents_20250724'!C3<>'VIM-Incidents_20250731'!C3,"Difference","OK") -> OK | D3: =IF('VIM-Incidents_20250724'!D3<>'VIM-Incidents_20250731'!D3,"Difference","OK") -> OK | E3: =IF('VIM-Incidents_20250724'!E3<>'VIM-Incidents_20250731'!E3,"Difference","OK") -> OK | F3: =IF('VIM-Incidents_20250724'!F3<>'VIM-Incidents_20250731'!F3,"Difference","OK") -> OK | G3: =IF('VIM-Incidents_20250724'!G3<>'VIM-Incidents_20250731'!G3,"Difference","OK") -> OK | H3: =IF('VIM-Incidents_20250724'!H3<>'VIM-Incidents_20250731'!H3,"Difference","OK") -> OK | ... S3: =IF('VIM-Incidents_20250724'!S3<>'VIM-Incidents_20250731'!S3,"Difference","OK") -> OK
A4: =IF('VIM-Incidents_20250724'!A4<>'VIM-Incidents_20250731'!A4,"Difference","OK") -> OK | B4: =IF('VIM-Incidents_20250724'!B4<>'VIM-Incidents_20250731'!B4,"Difference","OK") -> OK | C4: =IF('VIM-Incidents_20250724'!C4<>'VIM-Incidents_20250731'!C4,"Difference","OK") -> OK | D4: =IF('VIM-Incidents_20250724'!D4<>'VIM-Incidents_20250731'!D4,"Difference","OK") -> OK | E4: =IF('VIM-Incidents_20250724'!E4<>'VIM-Incidents_20250731'!E4,"Difference","OK") -> OK | F4: =IF('VIM-Incidents_20250724'!F4<>'VIM-Incidents_20250731'!F4,"Difference","OK") -> OK | G4: =IF('VIM-Incidents_20250724'!G4<>'VIM-Incidents_20250731'!G4,"Difference","OK") -> OK | H4: =IF('VIM-Incidents_20250724'!H4<>'VIM-Incidents_20250731'!H4,"Difference","OK") -> OK | ... S4: =IF('VIM-Incidents_20250724'!S4<>'VIM-Incidents_20250731'!S4,"Difference","OK") -> OK
A5: =IF('VIM-Incidents_20250724'!A5<>'VIM-Incidents_20250731'!A5,"Difference","OK") -> OK | B5: =IF('VIM-Incidents_20250724'!B5<>'VIM-Incidents_20250731'!B5,"Difference","OK") -> OK | C5: =IF('VIM-Incidents_20250724'!C5<>'VIM-Incidents_20250731'!C5,"Difference","OK") -> OK | D5: =IF('VIM-Incidents_20250724'!D5<>'VIM-Incidents_20250731'!D5,"Difference","OK") -> OK | E5: =IF('VIM-Incidents_20250724'!E5<>'VIM-Incidents_20250731'!E5,"Difference","OK") -> OK | F5: =IF('VIM-Incidents_20250724'!F5<>'VIM-Incidents_20250731'!F5,"Difference","OK") -> OK | G5: =IF('VIM-Incidents_20250724'!G5<>'VIM-Incidents_20250731'!G5,"Difference","OK") -> OK | H5: =IF('VIM-Incidents_20250724'!H5<>'VIM-Incidents_20250731'!H5,"Difference","OK") -> OK | ... S5: =IF('VIM-Incidents_20250724'!S5<>'VIM-Incidents_20250731'!S5,"Difference","OK") -> OK
A6: =IF('VIM-Incidents_20250724'!A6<>'VIM-Incidents_20250731'!A6,"Difference","OK") -> OK | B6: =IF('VIM-Incidents_20250724'!B6<>'VIM-Incidents_20250731'!B6,"Difference","OK") -> OK | C6: =IF('VIM-Incidents_20250724'!C6<>'VIM-Incidents_20250731'!C6,"Difference","OK") -> OK | D6: =IF('VIM-Incidents_20250724'!D6<>'VIM-Incidents_20250731'!D6,"Difference","OK") -> OK | E6: =IF('VIM-Incidents_20250724'!E6<>'VIM-Incidents_20250731'!E6,"Difference","OK") -> OK | F6: =IF('VIM-Incidents_20250724'!F6<>'VIM-Incidents_20250731'!F6,"Difference","OK") -> OK | G6: =IF('VIM-Incidents_20250724'!G6<>'VIM-Incidents_20250731'!G6,"Difference","OK") -> OK | H6: =IF('VIM-Incidents_20250724'!H6<>'VIM-Incidents_20250731'!H6,"Difference","OK") -> OK | ... S6: =IF('VIM-Incidents_20250724'!S6<>'VIM-Incidents_20250731'!S6,"Difference","OK") -> OK
A7: =IF('VIM-Incidents_20250724'!A7<>'VIM-Incidents_20250731'!A7,"Difference","OK") -> OK | B7: =IF('VIM-Incidents_20250724'!B7<>'VIM-Incidents_20250731'!B7,"Difference","OK") -> OK | C7: =IF('VIM-Incidents_20250724'!C7<>'VIM-Incidents_20250731'!C7,"Difference","OK") -> OK | D7: =IF('VIM-Incidents_20250724'!D7<>'VIM-Incidents_20250731'!D7,"Difference","OK") -> OK | E7: =IF('VIM-Incidents_20250724'!E7<>'VIM-Incidents_20250731'!E7,"Difference","OK") -> OK | F7: =IF('VIM-Incidents_20250724'!F7<>'VIM-Incidents_20250731'!F7,"Difference","OK") -> OK | G7: =IF('VIM-Incidents_20250724'!G7<>'VIM-Incidents_20250731'!G7,"Difference","OK") -> OK | H7: =IF('VIM-Incidents_20250724'!H7<>'VIM-Incidents_20250731'!H7,"Difference","OK") -> OK | ... S7: =IF('VIM-Incidents_20250724'!S7<>'VIM-Incidents_20250731'!S7,"Difference","OK") -> OK
A8: =IF('VIM-Incidents_20250724'!A8<>'VIM-Incidents_20250731'!A8,"Difference","OK") -> OK | B8: =IF('VIM-Incidents_20250724'!B8<>'VIM-Incidents_20250731'!B8,"Difference","OK") -> OK | C8: =IF('VIM-Incidents_20250724'!C8<>'VIM-Incidents_20250731'!C8,"Difference","OK") -> OK | D8: =IF('VIM-Incidents_20250724'!D8<>'VIM-Incidents_20250731'!D8,"Difference","OK") -> OK | E8: =IF('VIM-Incidents_20250724'!E8<>'VIM-Incidents_20250731'!E8,"Difference","OK") -> OK | F8: =IF('VIM-Incidents_20250724'!F8<>'VIM-Incidents_20250731'!F8,"Difference","OK") -> OK | G8: =IF('VIM-Incidents_20250724'!G8<>'VIM-Incidents_20250731'!G8,"Difference","OK") -> OK | H8: =IF('VIM-Incidents_20250724'!H8<>'VIM-Incidents_20250731'!H8,"Difference","OK") -> OK | ... S8: =IF('VIM-Incidents_20250724'!S8<>'VIM-Incidents_20250731'!S8,"Difference","OK") -> OK
A9: =IF('VIM-Incidents_20250724'!A9<>'VIM-Incidents_20250731'!A9,"Difference","OK") -> OK | B9: =IF('VIM-Incidents_20250724'!B9<>'VIM-Incidents_20250731'!B9,"Difference","OK") -> OK | C9: =IF('VIM-Incidents_20250724'!C9<>'VIM-Incidents_20250731'!C9,"Difference","OK") -> OK | D9: =IF('VIM-Incidents_20250724'!D9<>'VIM-Incidents_20250731'!D9,"Difference","OK") -> OK | E9: =IF('VIM-Incidents_20250724'!E9<>'VIM-Incidents_20250731'!E9,"Difference","OK") -> OK | F9: =IF('VIM-Incidents_20250724'!F9<>'VIM-Incidents_20250731'!F9,"Difference","OK") -> OK | G9: =IF('VIM-Incidents_20250724'!G9<>'VIM-Incidents_20250731'!G9,"Difference","OK") -> OK | H9: =IF('VIM-Incidents_20250724'!H9<>'VIM-Incidents_20250731'!H9,"Difference","OK") -> OK | ... S9: =IF('VIM-Incidents_20250724'!S9<>'VIM-Incidents_20250731'!S9,"Difference","OK") -> OK
A10: =IF('VIM-Incidents_20250724'!A10<>'VIM-Incidents_20250731'!A10,"Difference","OK") -> OK | B10: =IF('VIM-Incidents_20250724'!B10<>'VIM-Incidents_20250731'!B10,"Difference","OK") -> OK | C10: =IF('VIM-Incidents_20250724'!C10<>'VIM-Incidents_20250731'!C10,"Difference","OK") -> OK | D10: =IF('VIM-Incidents_20250724'!D10<>'VIM-Incidents_20250731'!D10,"Difference","OK") -> OK | E10: =IF('VIM-Incidents_20250724'!E10<>'VIM-Incidents_20250731'!E10,"Difference","OK") -> OK | F10: =IF('VIM-Incidents_20250724'!F10<>'VIM-Incidents_20250731'!F10,"Difference","OK") -> OK | G10: =IF('VIM-Incidents_20250724'!G10<>'VIM-Incidents_20250731'!G10,"Difference","OK") -> OK | H10: =IF('VIM-Incidents_20250724'!H10<>'VIM-Incidents_20250731'!H10,"Difference","OK") -> OK | ... S10: =IF('VIM-Incidents_20250724'!S10<>'VIM-Incidents_20250731'!S10,"Difference","OK") -> OK
A11: =IF('VIM-Incidents_20250724'!A11<>'VIM-Incidents_20250731'!A11,"Difference","OK") -> OK | B11: =IF('VIM-Incidents_20250724'!B11<>'VIM-Incidents_20250731'!B11,"Difference","OK") -> OK | C11: =IF('VIM-Incidents_20250724'!C11<>'VIM-Incidents_20250731'!C11,"Difference","OK") -> OK | D11: =IF('VIM-Incidents_20250724'!D11<>'VIM-Incidents_20250731'!D11,"Difference","OK") -> OK | E11: =IF('VIM-Incidents_20250724'!E11<>'VIM-Incidents_20250731'!E11,"Difference","OK") -> OK | F11: =IF('VIM-Incidents_20250724'!F11<>'VIM-Incidents_20250731'!F11,"Difference","OK") -> OK | G11: =IF('VIM-Incidents_20250724'!G11<>'VIM-Incidents_20250731'!G11,"Difference","OK") -> OK | H11: =IF('VIM-Incidents_20250724'!H11<>'VIM-Incidents_20250731'!H11,"Difference","OK") -> OK | ... S11: =IF('VIM-Incidents_20250724'!S11<>'VIM-Incidents_20250731'!S11,"Difference","OK") -> OK
A12: =IF('VIM-Incidents_20250724'!A12<>'VIM-Incidents_20250731'!A12,"Difference","OK") -> OK | B12: =IF('VIM-Incidents_20250724'!B12<>'VIM-Incidents_20250731'!B12,"Difference","OK") -> OK | C12: =IF('VIM-Incidents_20250724'!C12<>'VIM-Incidents_20250731'!C12,"Difference","OK") -> OK | D12: =IF('VIM-Incidents_20250724'!D12<>'VIM-Incidents_20250731'!D12,"Difference","OK") -> OK | E12: =IF('VIM-Incidents_20250724'!E12<>'VIM-Incidents_20250731'!E12,"Difference","OK") -> OK | F12: =IF('VIM-Incidents_20250724'!F12<>'VIM-Incidents_20250731'!F12,"Difference","OK") -> OK | G12: =IF('VIM-Incidents_20250724'!G12<>'VIM-Incidents_20250731'!G12,"Difference","OK") -> OK | H12: =IF('VIM-Incidents_20250724'!H12<>'VIM-Incidents_20250731'!H12,"Difference","OK") -> OK | ... S12: =IF('VIM-Incidents_20250724'!S12<>'VIM-Incidents_20250731'!S12,"Difference","OK") -> OK
... A210: =IF('VIM-Incidents_20250724'!A210<>'VIM-Incidents_20250731'!A210,"Difference","OK") -> OK | B210: =IF('VIM-Incidents_20250724'!B210<>'VIM-Incidents_20250731'!B210,"Difference","OK") -> OK | C210: =IF('VIM-Incidents_20250724'!C210<>'VIM-Incidents_20250731'!C210,"Difference","OK") -> OK | D210: =IF('VIM-Incidents_20250724'!D210<>'VIM-Incidents_20250731'!D210,"Difference","OK") -> OK | E210: =IF('VIM-Incidents_20250724'!E210<>'VIM-Incidents_20250731'!E210,"Difference","OK") -> OK | F210: =IF('VIM-Incidents_20250724'!F210<>'VIM-Incidents_20250731'!F210,"Difference","OK") -> OK | G210: =IF('VIM-Incidents_20250724'!G210<>'VIM-Incidents_20250731'!G210,"Difference","OK") -> OK | H210: =IF('VIM-Incidents_20250724'!H210<>'VIM-Incidents_20250731'!H210,"Difference","OK") -> OK | ... S210: =IF('VIM-Incidents_20250724'!S210<>'VIM-Incidents_20250731'!S210,"Difference","OK") -> OK

Sheet VIM-Incidents_W24
A1: ID | B1: FutureNow Ticket | C1: External ID | D1: ARE | E1: Created On | F1: Due by | G1: Reported By | H1: Message Processor | I1: Last Changed on | J1: Last Changed By | K1: Priority | L1: Status | M1: Description | N1: Support Team | O1: System ID | Q1: Open Days | R1: Open 7D+ | S1: Open 30D+
A2: 6000127070 | B2: INC41987224 | D2: 5975 | E2: 45663 | G2: Lenka Michalusova (GBS CEE P2P CZ AP 2 4 / Z002HBHR) | H2: Ulrich Rauch / 81739 Muenchen | I2: 45727 | J2: RFC_FITS | K2: 4: Low | L2: Confirm_Closed | M2: VIM- missing tax code | N2: SIE_S4P_RS Siemens S4P - Readsoft | Q2: =DATEDIF(E2,I2,"d") -> 64 | R2: =IF($Q2>7,1,0) -> 1 | S2: =IF($Q2>30,1,0) -> 1
A3: 6000127209 | B3: INC41997245 | D3: 5975 | E3: 45664 | G3: Simon Kostovski (GBS CEE P2P CZ AP 3 2 / Z003DW1N) | H3: Albert Galek | I3: 45673 | J3: RFC_FITS | K3: 3: Medium | L3: Confirm_Closed | M3: INC41861079 not solved but it was closed | N3: SIE_S4P_RS Siemens S4P - Readsoft | Q3: =DATEDIF(E3,I3,"d") -> 9 | R3: =IF($Q3>7,1,0) -> 1 | S3: =IF($Q3>30,1,0) -> 0
A4: 6000127632 | B4: INC42022656 | D4: 5975 | E4: 45667 | G4: Barbora Struskova (GBS CEE P2P CZ AP 2 4 / Z002HZ1U) | H4: Ilona Splichalova | I4: 45679 | J4: RFC_FITS | K4: 4: Low | L4: Confirm_Closed | M4: automatic text | N4: SIE_S4P_RS Siemens S4P - Readsoft | Q4: =DATEDIF(E4,I4,"d") -> 12 | R4: =IF($Q4>7,1,0) -> 1 | S4: =IF($Q4>30,1,0) -> 0
A5: 6000128352 | D5: 3003 | E5: 45674 | G5: Ilona Splichalova (DI IT ERP CZ FICO / Z002Z2VA) | H5: Albert Galek | I5: 45688 | J5: SAP SOLUTION MANAGER S1A | K5: 3: Medium | L5: Confirm_Closed | M5: DP 2807 in S4P: please check the status | N5: SIE_S4P_RS Siemens S4P - Readsoft | Q5: =DATEDIF(E5,I5,"d") -> 14 | R5: =IF($Q5>7,1,0) -> 1 | S5: =IF($Q5>30,1,0) -> 0
A6: 6000128500 | B6: INC42075263 | D6: 7092 | E6: 45677 | G6: Lena Osterhus (CE SEC TPC / Z001MA1B) | H6: Ilona Splichalova | I6: 45684 | J6: RFC_FITS | K6: 4: Low | L6: Confirm_Closed | M6: Falsche Emailadresse bei Readsoft/ WebCycle | N6: SIE_S4P_RS Siemens S4P - Readsoft | Q6: =DATEDIF(E6,I6,"d") -> 7 | R6: =IF($Q6>7,1,0) -> 0 | S6: =IF($Q6>30,1,0) -> 0
A7: 6000128546 | B7: INC42077895 | D7: SRE | E7: 45677 | G7: Zdenek Cifka (GBS CEE P2P CZ AP 2 3 / Z003JPCS) | H7: Ilona Splichalova | I7: 45805 | J7: Ulrich Rauch | K7: 3: Medium | L7: In Process | M7: VIM ID's 2391 and 2623 - after posting the payment block was'nt entered and approval workflow was'nt started | N7: SIE_S4P_RS Siemens S4P - Readsoft | Q7: =DATEDIF(E7,TODAY(),"d") -> 330 | R7: =IF($Q7>7,1,0) -> 1 | S7: =IF($Q7>30,1,0) -> 1
A8: 6000128759 | B8: INC42093959 | D8: 7092 | E8: 45679 | G8: Andreas Mengele (MAP DF&PCM PCM / Z001THRJ) | H8: Ilona Splichalova | I8: 45686 | J8: RFC_FITS | K8: 4: Low | L8: Confirm_Closed | M8: Umstellung der Rechte von Susanne Spiegl auf Philipp Rath | N8: SIE_S4P_RS Siemens S4P - Readsoft | Q8: =DATEDIF(E8,TODAY(),"d") -> 328 | R8: =IF($Q8>7,1,0) -> 1 | S8: =IF($Q8>30,1,0) -> 1
A9: 6000129022 | B9: INC42106952 | D9: 5975 | E9: 45680 | G9: Renata Staricna (GBS CEE P2P CZ AP 2 4 / Z0046K6B) | H9: Ilona Splichalova | I9: 45705 | J9: RFC_FITS | K9: 4: Low | L9: Confirm_Closed | M9: Reminder - automatic answers | N9: SIE_S4P_RS Siemens S4P - Readsoft | Q9: =DATEDIF(E9,TODAY(),"d") -> 327 | R9: =IF($Q9>7,1,0) -> 1 | S9: =IF($Q9>30,1,0) -> 1
A10: 6000129245 | B10: INC42120663 | D10: 7092 | E10: 45684 | G10: Veronika Andres (IT ECP FPS T&CS / Z0029JJZ) | H10: Ilona Splichalova | I10: 45691 | J10: RFC_FITS | K10: 4: Low | L10: Confirm_Closed | M10: WebCycle User locked | N10: SIE_S4P_RS Siemens S4P - Readsoft | Q10: =DATEDIF(E10,TODAY(),"d") -> 323 | R10: =IF($Q10>7,1,0) -> 1 | S10: =IF($Q10>30,1,0) -> 1
A11: 6000129304 | B11: INC42122188 | D11: SRE | E11: 45684 | G11: Tobias Moest (SRE FIN AR 2 / Z000F12V) | H11: Albert Galek | I11: 45693 | J11: RFC_FITS | K11: 4: Low | L11: Confirm_Closed | M11: S4P 100 - VIM: Vorgang aus Klärungs-WF nicht vorhanden | N11: SIE_S4P_RS Siemens S4P - Readsoft | Q11: =DATEDIF(E11,TODAY(),"d") -> 323 | R11: =IF($Q11>7,1,0) -> 1 | S11: =IF($Q11>30,1,0) -> 1
A12: 6000129653 | D12: 3003 | E12: 45686 | G12: Ilona Splichalova (DI IT ERP CZ FICO / Z002Z2VA) | H12: Ilona Splichalova | I12: 45782 | J12: SAP SOLUTION MANAGER S1A | K12: 3: Medium | L12: Confirm_Closed | M12: VIM 2756 und 2774 - Error by 3 step approval WF by Construction Invoices | N12: SIE_S4P_RS Siemens S4P - Readsoft | Q12: =DATEDIF(E12,TODAY(),"d") -> 321 | R12: =IF($Q12>7,1,0) -> 1 | S12: =IF($Q12>30,1,0) -> 1
A13: 6000129990 | B13: INC42154604 | D13: SRE | E13: 45688 | G13: Zdenek Cifka (GBS CEE P2P CZ AP 2 3 / Z003JPCS) | H13: Albert Galek | I13: 45699 | J13: RFC_FITS | K13: 3: Medium | L13: Confirm_Closed | M13: Is not possible to start the approval workflow for VIM ID 2515 | N13: SIE_S4P_RS Siemens S4P - Readsoft | Q13: =DATEDIF(E13,TODAY(),"d") -> 319 | R13: =IF($Q13>7,1,0) -> 1 | S13: =IF($Q13>30,1,0) -> 1
A14: 6000130122 | B14: INC42161605 | D14: 3014 | E14: 45691 | G14: Pompilia Bianca Trifa (DI MC GMC MF-EWN PU-BUZ FIN LOG 1-2 / | H14: Ulrich Rauch / 81739 Muenchen | I14: 45708 | J14: RFC_FITS | K14: 3: Medium | L14: Confirm_Closed | M14: S4P VIM - Invoices in Approval steps (direct materials) not visible to the approver | N14: SIE_S4P_RS Siemens S4P - Readsoft | Q14: 38 | R14: =IF($Q14>7,1,0) -> 1 | S14: =IF($Q14>30,1,0) -> 1
A15: 6000130131 | B15: INC42161726 | D15: 3014 | E15: 45691 | G15: Andreea Laura Boran (DI MC GMC MF-EWN PU-BUZ FIN LOG 1-2 / Z | H15: Ulrich Rauch / 81739 Muenchen | I15: 45708 | J15: RFC_FITS | K15: 3: Medium | L15: Confirm_Closed | M15: S4P - VIM error in invoice approval | N15: SIE_S4P_RS Siemens S4P - Readsoft | Q15: =DATEDIF(E15,TODAY(),"d") -> 316 | R15: =IF($Q15>7,1,0) -> 1 | S15: =IF($Q15>30,1,0) -> 1
A16: 6000130842 | B16: INC42203263 | D16: 3003 | E16: 45698 | G16: Helge Preiss (SRE DP PM EU / Z001WZ3K) | H16: Ulrich Rauch / 81739 Muenchen | I16: 45824 | J16: Ulrich Rauch | K16: 3: Medium | L16: Proposed Solution | M16: S4P VIM FIORI Approval Invoice Management Fehlermeldung | N16: SIE_S4P_RS Siemens S4P - Readsoft | Q16: =DATEDIF(E16,TODAY(),"d") -> 309 | R16: =IF($Q16>7,1,0) -> 1 | S16: =IF($Q16>30,1,0) -> 1
A17: 6000130889 | B17: INC42205466 | D17: 7092 | E17: 45698 | G17: Laura Hochwind (IT ECP FPS AP1 / Z003NVNW) | H17: Ulrich Rauch / 81739 Muenchen | I17: 45705 | J17: RFC_FITS | K17: 3: Medium | L17: Confirm_Closed | M17: Add Substitute for Webcycle Readsoft | N17: SIE_S4P_RS Siemens S4P - Readsoft | Q17: =DATEDIF(E17,TODAY(),"d") -> 309 | R17: =IF($Q17>7,1,0) -> 1 | S17: =IF($Q17>30,1,0) -> 1
A18: 6000131438 | B18: INC42234456 | D18: 3003 | E18: 45701 | G18: Mario Beck (SRE DP PM EU / Z00109RY) | H18: Mr. Ramesh Itamsetti | I18: 45824 | J18: Ulrich Rauch | K18: 3: Medium | L18: Proposed Solution | M18: S4P 100 VIM - Fehlermeldung bei WF-Freigabe | N18: SIE_S4P_RS Siemens S4P - Readsoft | Q18: =DATEDIF(E18,TODAY(),"d") -> 306 | R18: =IF($Q18>7,1,0) -> 1 | S18: =IF($Q18>30,1,0) -> 1
A19: 6000131514 | D19: 7092 | E19: 45702 | G19: Ulrich Rauch (IT ECP ERP-CP ARC2 / Z00060NO) | H19: Ulrich Rauch / 81739 Muenchen | I19: 45723 | J19: SAP SOLUTION MANAGER S1A | K19: 3: Medium | L19: Confirm_Closed | M19: VIM: VIM Authorization issue in Exceptions App (mid-term solution) | N19: SIE_S4P_RS Siemens S4P - Readsoft | Q19: =DATEDIF(E19,TODAY(),"d") -> 305 | R19: =IF($Q19>7,1,0) -> 1 | S19: =IF($Q19>30,1,0) -> 1
A20: 6000131715 | B20: INC42252236 | D20: 5975 | E20: 45705 | G20: Pavel Mego (GBS CEE P2P CZ AP 2 4 / Z001SCDJ) | H20: Ulrich Rauch / 81739 Muenchen | I20: 45713 | J20: RFC_FITS | K20: 4: Low | L20: Confirm_Closed | M20: duplicity check | N20: SIE_S4P_RS Siemens S4P - Readsoft | Q20: =DATEDIF(E20,TODAY(),"d") -> 302 | R20: =IF($Q20>7,1,0) -> 1 | S20: =IF($Q20>30,1,0) -> 1
A21: 6000132000 | B21: INC42270698 | D21: SRE | E21: 45707 | G21: Zdenek Cifka (GBS CEE P2P CZ AP 2 3 / Z003JPCS) | H21: Albert Galek | I21: 45735 | J21: RFC_FITS | K21: 3: Medium | L21: Confirm_Closed | M21: In VIM it is not possible to post the recurring documents, which contain multiple Profit Centers - VIM ID 3988 and 4340 | N21: SIE_S4P_RS Siemens S4P - Readsoft | Q21: =DATEDIF(E21,TODAY(),"d") -> 300 | R21: =IF($Q21>7,1,0) -> 1 | S21: =IF($Q21>30,1,0) -> 1
A22: 6000132651 | B22: INC42313692 | D22: 3003 | E22: 45714 | G22: Mario Beck (SRE DP PM EU / Z00109RY) | H22: Albert Galek | I22: 45723 | J22: RFC_FITS | K22: 4: Low | L22: Confirm_Closed | M22: S4P 100 VIM - #2777 can't be approved (new error message) | N22: SIE_S4P_RS Siemens S4P - Readsoft | Q22: =DATEDIF(E22,TODAY(),"d") -> 293 | R22: =IF($Q22>7,1,0) -> 1 | S22: =IF($Q22>30,1,0) -> 1
A23: 6000133013 | B23: INC42339428 | D23: 5975 | E23: 45719 | G23: Jitka Krnavkova (GBS CEE P2P CZ AP 2 4 / Z002HBHS) | H23: Ilona Splichalova | I23: 45734 | J23: RFC_FITS | K23: 4: Low | L23: Confirm_Closed | M23: Add user to ICFR group_READSOFT | N23: SIE_S4P_RS Siemens S4P - Readsoft | Q23: =DATEDIF(E23,TODAY(),"d") -> 288 | R23: =IF($Q23>7,1,0) -> 1 | S23: =IF($Q23>30,1,0) -> 1
A24: 6000133061 | B24: INC42342340 | D24: SRE | E24: 45719 | G24: Zdenek Cifka (GBS CEE P2P CZ AP 2 3 / Z003JPCS) | H24: Ilona Splichalova | I24: 45735 | J24: RFC_FITS | K24: 3: Medium | L24: Confirm_Closed | M24: VIM ID 1785 - approval workflow wasn't started but nevertheless is situated in VIM WP in My pending section | N24: SIE_S4P_RS Siemens S4P - Readsoft | Q24: =DATEDIF(E24,TODAY(),"d") -> 288 | R24: =IF($Q24>7,1,0) -> 1 | S24: =IF($Q24>30,1,0) -> 1
A25: 6000133063 | B25: INC42342645 | D25: 5220 | E25: 45719 | G25: Simona-Elena Kovar (CF R EEA PP PI / Z0046E1M) | H25: Ilona Splichalova | I25: 45778 | J25: RFC_FITS | K25: 4: Low | L25: Confirm_Closed | M25: GR posted, the payment block was removed in the background -> VIM workflow NOT completed | N25: SIE_S4P_RS Siemens S4P - Readsoft | Q25: =DATEDIF(E25,TODAY(),"d") -> 288 | R25: =IF($Q25>7,1,0) -> 1 | S25: =IF($Q25>30,1,0) -> 1
A26: 6000133075 | B26: INC42342669 | D26: 5220 | E26: 45719 | G26: Simona-Elena Kovar (CF R EEA PP PI / Z0046E1M) | H26: Albert Galek | I26: 45758 | J26: RFC_FITS | K26: 4: Low | L26: Confirm_Closed | M26: the document requires a technical approval although there is no price or quantity deviation | N26: SIE_S4P_RS Siemens S4P - Readsoft | Q26: =DATEDIF(E26,TODAY(),"d") -> 288 | R26: =IF($Q26>7,1,0) -> 1 | S26: =IF($Q26>30,1,0) -> 1
A27: 6000133085 | D27: 7092 | E27: 45719 | G27: Ulrich Rauch (IT ECP ERP-CP ARC2 / Z00060NO) | H27: Albert Galek | I27: 45731 | J27: SAP SOLUTION MANAGER S1A | K27: 3: Medium | L27: Confirm_Closed | M27: VIM: direct material PO: not able to choose non preferred approver | N27: SIE_S4P_RS Siemens S4P - Readsoft | Q27: =DATEDIF(E27,TODAY(),"d") -> 288 | R27: =IF($Q27>7,1,0) -> 1 | S27: =IF($Q27>30,1,0) -> 1
A28: 6000133086 | D28: 7092 | E28: 45719 | G28: Ulrich Rauch (IT ECP ERP-CP ARC2 / Z00060NO) | H28: Albert Galek | I28: 45773 | J28: SAP SOLUTION MANAGER S1A | K28: 3: Medium | L28: Confirm_Closed | M28: VIM ID 1785 and 5352 - approval workflow wasn't started but nevertheless is s | N28: SIE_S4P_RS Siemens S4P - Readsoft | Q28: =DATEDIF(E28,TODAY(),"d") -> 288 | R28: =IF($Q28>7,1,0) -> 1 | S28: =IF($Q28>30,1,0) -> 1
A29: 6000133087 | D29: 7092 | E29: 45719 | G29: Ulrich Rauch (IT ECP ERP-CP ARC2 / Z00060NO) | H29: Ilona Splichalova | I29: 45807 | J29: SAP SOLUTION MANAGER S1A | K29: 3: Medium | L29: Confirm_Closed | M29: VIM: different statuses in VIM Workplace and VIM Analytics | N29: SIE_S4P_RS Siemens S4P - Readsoft | Q29: =DATEDIF(E29,TODAY(),"d") -> 288 | R29: =IF($Q29>7,1,0) -> 1 | S29: =IF($Q29>30,1,0) -> 1
A30: 6000133442 | D30: 3003 | E30: 45722 | G30: Ilona Splichalova (DI IT ERP CZ FICO / Z002Z2VA) | H30: Ilona Splichalova | I30: 45786 | J30: SAP SOLUTION MANAGER S1A | K30: 3: Medium | L30: Confirm_Closed | M30: In VIM is not possible to cancel the invoice - DP 4288 | N30: SIE_S4P_RS Siemens S4P - Readsoft | Q30: =DATEDIF(E30,TODAY(),"d") -> 285 | R30: =IF($Q30>7,1,0) -> 1 | S30: =IF($Q30>30,1,0) -> 1
A31: 6000133644 | B31: INC42377517 | D31: 3014 | E31: 45723 | G31: Simon Kostovski (GBS CEE P2P CZ AP PE 2 / Z003DW1N) | H31: Albert Galek | I31: 45789 | J31: Ilona Splichalova | K31: 3: Medium | L31: In Process | M31: S4P Please adjust the VAT date to be identical with the invoice date for Company code 3014 | N31: SIE_S4P_RS Siemens S4P - Readsoft | Q31: =DATEDIF(E31,TODAY(),"d") -> 284 | R31: =IF($Q31>7,1,0) -> 1 | S31: =IF($Q31>30,1,0) -> 1
A32: 6000133647 | B32: INC42377569 | D32: 5975 | E32: 45723 | G32: Jan Binder (GBS CEE P2P CZ AP 2 2 / Z00435WC) | H32: Ilona Splichalova | I32: 45733 | J32: RFC_FITS | K32: 4: Low | L32: Confirm_Closed | M32: Receipt of invoices and posting in a different month/period. | N32: SIE_S4P_RS Siemens S4P - Readsoft | Q32: =DATEDIF(E32,TODAY(),"d") -> 284 | R32: =IF($Q32>7,1,0) -> 1 | S32: =IF($Q32>30,1,0) -> 1
A33: 6000133780 | B33: INC42386307 | D33: 3014 | E33: 45726 | G33: Andrei Vulpescu (DI MC GMC MF-EWN PU-BUZ FIN / Z00172BA) | H33: Albert Galek | I33: 45741 | J33: RFC_FITS | K33: 4: Low | L33: Confirm_Closed | M33: I cannot approve invoice release | N33: SIE_S4P_RS Siemens S4P - Readsoft | Q33: =DATEDIF(E33,TODAY(),"d") -> 281 | R33: =IF($Q33>7,1,0) -> 1 | S33: =IF($Q33>30,1,0) -> 1
A34: 6000133782 | B34: INC42386439 | D34: SRE | E34: 45726 | G34: Zdenek Cifka (GBS CEE P2P CZ AP 2 3 / Z003JPCS) | H34: Albert Galek | I34: 45735 | J34: RFC_FITS | K34: 3: Medium | L34: Confirm_Closed | M34: At VIM ID's 2977 and 1961 it's not possible to recall the approval workflow because they are situated in VIM WP in My co | N34: SIE_S4P_RS Siemens S4P - Readsoft | Q34: =DATEDIF(E34,TODAY(),"d") -> 281 | R34: =IF($Q34>7,1,0) -> 1 | S34: =IF($Q34>30,1,0) -> 1
A35: 6000133815 | B35: INC42387821 | D35: SRE | E35: 45726 | G35: Zdenek Cifka (GBS CEE P2P CZ AP 2 3 / Z003JPCS) | H35: Albert Galek | I35: 45748 | J35: RFC_FITS | K35: 3: Medium | L35: Confirm_Closed | M35: VIM ID 5033 - it's not possible to start the approval workflow manually for the specific person. | N35: SIE_S4P_RS Siemens S4P - Readsoft | Q35: =DATEDIF(E35,TODAY(),"d") -> 281 | R35: =IF($Q35>7,1,0) -> 1 | S35: =IF($Q35>30,1,0) -> 1
A36: 6000133897 | D36: 5975 | E36: 45727 | G36: Ilona Splichalova (DI IT ERP CZ FICO / Z002Z2VA) | H36: Albert Galek | I36: 45751 | J36: SAP SOLUTION MANAGER S1A | K36: 3: Medium | L36: Confirm_Closed | M36: VIM Table U-date Clarifications | N36: SIE_S4P_RS Siemens S4P - Readsoft | Q36: =DATEDIF(E36,TODAY(),"d") -> 280 | R36: =IF($Q36>7,1,0) -> 1 | S36: =IF($Q36>30,1,0) -> 1
A37: 6000134052 | B37: INC42401853 | D37: 3014 | E37: 45728 | G37: Ivana Tomisova (GBS CEE P2P CZ AP 3 2 / Z004PK7A) | H37: Mr. Silambarasan Vasu | I37: 45819 | K37: 4: Low | L37: Forwarded | M37: 3014 - ICC invoice not visible in VIM workplace | N37: MM - Materials Management | Q37: =DATEDIF(E37,TODAY(),"d") -> 279 | R37: =IF($Q37>7,1,0) -> 1 | S37: =IF($Q37>30,1,0) -> 1
A38: 6000134157 | B38: INC42406593 | D38: 5975 | E38: 45729 | G38: Pavel Mego (GBS CEE P2P CZ AP 2 4 / Z001SCDJ) | H38: Ilona Splichalova | I38: 45737 | J38: RFC_FITS | K38: 4: Low | L38: Confirm_Closed | M38: Stucked Webcycle | N38: SIE_S4P_RS Siemens S4P - Readsoft | Q38: =DATEDIF(E38,TODAY(),"d") -> 278 | R38: =IF($Q38>7,1,0) -> 1 | S38: =IF($Q38>30,1,0) -> 1
A39: 6000134167 | D39: 7092 | E39: 45729 | G39: Muskan Khanum Nagad (IT ECP ERP-CP / Z0053CPH) | H39: Albert Galek | I39: 45792 | J39: SAP SOLUTION MANAGER S1A | K39: 3: Medium | L39: Confirm_Closed | M39: Abap programming error in S4P | N39: SIE_S4P_RS Siemens S4P - Readsoft | Q39: =DATEDIF(E39,TODAY(),"d") -> 278 | R39: =IF($Q39>7,1,0) -> 1 | S39: =IF($Q39>30,1,0) -> 1
A40: 6000134304 | B40: INC42414880 | D40: 7011 | E40: 45729 | G40: Cosmin-Ovidiu Sarbu (DI MC GMC MF-EWN PU-BUZ FIN BC / Z0026A | H40: Ilona Splichalova | I40: 45782 | J40: RFC_FITS | K40: 4: Low | L40: Confirm_Closed | M40: Approval of invoices in VIM according to SAT | N40: SIE_S4P_RS Siemens S4P - Readsoft | Q40: =DATEDIF(E40,TODAY(),"d") -> 278 | R40: =IF($Q40>7,1,0) -> 1 | S40: =IF($Q40>30,1,0) -> 1
...

Sheet VIM-Incidents_W25
A1: ID | B1: FutureNow Ticket | C1: External ID | D1: ARE | E1: Created On | F1: Due by | G1: Reported By | H1: Message Processor | I1: Last Changed on | J1: Last Changed By | K1: Priority | L1: Status | M1: Description | N1: Support Team | O1: System ID | Q1: Open Days | R1: Open 7D+ | S1: Open 30D+
A2: 6000127070 | B2: INC41987224 | D2: 5975 | E2: 45663 | G2: Lenka Michalusova (GBS CEE P2P CZ AP 2 4 / Z002HBHR) | H2: Ulrich Rauch / 81739 Muenchen | I2: 45727 | J2: RFC_FITS | K2: 4: Low | L2: Confirm_Closed | M2: VIM- missing tax code | N2: SIE_S4P_RS Siemens S4P - Readsoft | Q2: =DATEDIF(E2,I2,"d") -> 64 | R2: =IF($Q2>7,1,0) -> 1 | S2: =IF($Q2>30,1,0) -> 1
A3: 6000127209 | B3: INC41997245 | D3: 5975 | E3: 45664 | G3: Simon Kostovski (GBS CEE P2P CZ AP 3 2 / Z003DW1N) | H3: Albert Galek | I3: 45673 | J3: RFC_FITS | K3: 3: Medium | L3: Confirm_Closed | M3: INC41861079 not solved but it was closed | N3: SIE_S4P_RS Siemens S4P - Readsoft | Q3: =DATEDIF(E3,I3,"d") -> 9 | R3: =IF($Q3>7,1,0) -> 1 | S3: =IF($Q3>30,1,0) -> 0
A4: 6000127632 | B4: INC42022656 | D4: 5975 | E4: 45667 | G4: Barbora Struskova (GBS CEE P2P CZ AP 2 4 / Z002HZ1U) | H4: Ilona Splichalova | I4: 45679 | J4: RFC_FITS | K4: 4: Low | L4: Confirm_Closed | M4: automatic text | N4: SIE_S4P_RS Siemens S4P - Readsoft | Q4: =DATEDIF(E4,I4,"d") -> 12 | R4: =IF($Q4>7,1,0) -> 1 | S4: =IF($Q4>30,1,0) -> 0
A5: 6000128352 | D5: 3003 | E5: 45674 | G5: Ilona Splichalova (DI IT ERP CZ FICO / Z002Z2VA) | H5: Albert Galek | I5: 45688 | J5: SAP SOLUTION MANAGER S1A | K5: 3: Medium | L5: Confirm_Closed | M5: DP 2807 in S4P: please check the status | N5: SIE_S4P_RS Siemens S4P - Readsoft | Q5: =DATEDIF(E5,I5,"d") -> 14 | R5: =IF($Q5>7,1,0) -> 1 | S5: =IF($Q5>30,1,0) -> 0
A6: 6000128500 | B6: INC42075263 | D6: 7092 | E6: 45677 | G6: Lena Osterhus (CE SEC TPC / Z001MA1B) | H6: Ilona Splichalova | I6: 45684 | J6: RFC_FITS | K6: 4: Low | L6: Confirm_Closed | M6: Falsche Emailadresse bei Readsoft/ WebCycle | N6: SIE_S4P_RS Siemens S4P - Readsoft | Q6: =DATEDIF(E6,I6,"d") -> 7 | R6: =IF($Q6>7,1,0) -> 0 | S6: =IF($Q6>30,1,0) -> 0
A7: 6000128546 | B7: INC42077895 | D7: SRE | E7: 45677 | G7: Zdenek Cifka (GBS CEE P2P CZ AP 2 3 / Z003JPCS) | H7: Ilona Splichalova | I7: 45805 | J7: Ulrich Rauch | K7: 3: Medium | L7: In Process | M7: VIM ID's 2391 and 2623 - after posting the payment block was'nt entered and approval workflow was'nt started | N7: SIE_S4P_RS Siemens S4P - Readsoft | Q7: =DATEDIF(E7,TODAY(),"d") -> 330 | R7: =IF($Q7>7,1,0) -> 1 | S7: =IF($Q7>30,1,0) -> 1
A8: 6000128759 | B8: INC42093959 | D8: 7092 | E8: 45679 | G8: Andreas Mengele (MAP DF&PCM PCM / Z001THRJ) | H8: Ilona Splichalova | I8: 45686 | J8: RFC_FITS | K8: 4: Low | L8: Confirm_Closed | M8: Umstellung der Rechte von Susanne Spiegl auf Philipp Rath | N8: SIE_S4P_RS Siemens S4P - Readsoft | Q8: =DATEDIF(E8,TODAY(),"d") -> 328 | R8: =IF($Q8>7,1,0) -> 1 | S8: =IF($Q8>30,1,0) -> 1
A9: 6000129022 | B9: INC42106952 | D9: 5975 | E9: 45680 | G9: Renata Staricna (GBS CEE P2P CZ AP 2 4 / Z0046K6B) | H9: Ilona Splichalova | I9: 45705 | J9: RFC_FITS | K9: 4: Low | L9: Confirm_Closed | M9: Reminder - automatic answers | N9: SIE_S4P_RS Siemens S4P - Readsoft | Q9: =DATEDIF(E9,TODAY(),"d") -> 327 | R9: =IF($Q9>7,1,0) -> 1 | S9: =IF($Q9>30,1,0) -> 1
A10: 6000129245 | B10: INC42120663 | D10: 7092 | E10: 45684 | G10: Veronika Andres (IT ECP FPS T&CS / Z0029JJZ) | H10: Ilona Splichalova | I10: 45691 | J10: RFC_FITS | K10: 4: Low | L10: Confirm_Closed | M10: WebCycle User locked | N10: SIE_S4P_RS Siemens S4P - Readsoft | Q10: =DATEDIF(E10,TODAY(),"d") -> 323 | R10: =IF($Q10>7,1,0) -> 1 | S10: =IF($Q10>30,1,0) -> 1
A11: 6000129304 | B11: INC42122188 | D11: SRE | E11: 45684 | G11: Tobias Moest (SRE FIN AR 2 / Z000F12V) | H11: Albert Galek | I11: 45693 | J11: RFC_FITS | K11: 4: Low | L11: Confirm_Closed | M11: S4P 100 - VIM: Vorgang aus Klärungs-WF nicht vorhanden | N11: SIE_S4P_RS Siemens S4P - Readsoft | Q11: =DATEDIF(E11,TODAY(),"d") -> 323 | R11: =IF($Q11>7,1,0) -> 1 | S11: =IF($Q11>30,1,0) -> 1
A12: 6000129653 | D12: 3003 | E12: 45686 | G12: Ilona Splichalova (DI IT ERP CZ FICO / Z002Z2VA) | H12: Ilona Splichalova | I12: 45782 | J12: SAP SOLUTION MANAGER S1A | K12: 3: Medium | L12: Confirm_Closed | M12: VIM 2756 und 2774 - Error by 3 step approval WF by Construction Invoices | N12: SIE_S4P_RS Siemens S4P - Readsoft | Q12: =DATEDIF(E12,TODAY(),"d") -> 321 | R12: =IF($Q12>7,1,0) -> 1 | S12: =IF($Q12>30,1,0) -> 1
A13: 6000129990 | B13: INC42154604 | D13: SRE | E13: 45688 | G13: Zdenek Cifka (GBS CEE P2P CZ AP 2 3 / Z003JPCS) | H13: Albert Galek | I13: 45699 | J13: RFC_FITS | K13: 3: Medium | L13: Confirm_Closed | M13: Is not possible to start the approval workflow for VIM ID 2515 | N13: SIE_S4P_RS Siemens S4P - Readsoft | Q13: =DATEDIF(E13,TODAY(),"d") -> 319 | R13: =IF($Q13>7,1,0) -> 1 | S13: =IF($Q13>30,1,0) -> 1
A14: 6000130122 | B14: INC42161605 | D14: 3014 | E14: 45691 | G14: Pompilia Bianca Trifa (DI MC GMC MF-EWN PU-BUZ FIN LOG 1-2 / | H14: Ulrich Rauch / 81739 Muenchen | I14: 45708 | J14: RFC_FITS | K14: 3: Medium | L14: Confirm_Closed | M14: S4P VIM - Invoices in Approval steps (direct materials) not visible to the approver | N14: SIE_S4P_RS Siemens S4P - Readsoft | Q14: 38 | R14: =IF($Q14>7,1,0) -> 1 | S14: =IF($Q14>30,1,0) -> 1
A15: 6000130131 | B15: INC42161726 | D15: 3014 | E15: 45691 | G15: Andreea Laura Boran (DI MC GMC MF-EWN PU-BUZ FIN LOG 1-2 / Z | H15: Ulrich Rauch / 81739 Muenchen | I15: 45708 | J15: RFC_FITS | K15: 3: Medium | L15: Confirm_Closed | M15: S4P - VIM error in invoice approval | N15: SIE_S4P_RS Siemens S4P - Readsoft | Q15: =DATEDIF(E15,TODAY(),"d") -> 316 | R15: =IF($Q15>7,1,0) -> 1 | S15: =IF($Q15>30,1,0) -> 1
A16: 6000130842 | B16: INC42203263 | D16: 3003 | E16: 45698 | G16: Helge Preiss (SRE DP PM EU / Z001WZ3K) | H16: Albert Galek | I16: 45824 | J16: Ulrich Rauch | K16: 3: Medium | L16: Proposed Solution | M16: S4P VIM FIORI Approval Invoice Management Fehlermeldung | N16: SIE_S4P_RS Siemens S4P - Readsoft | Q16: =DATEDIF(E16,I16,"d") -> 126 | R16: =IF($Q16>7,1,0) -> 1 | S16: =IF($Q16>30,1,0) -> 1
A17: 6000130889 | B17: INC42205466 | D17: 7092 | E17: 45698 | G17: Laura Hochwind (IT ECP FPS AP1 / Z003NVNW) | H17: Ulrich Rauch / 81739 Muenchen | I17: 45705 | J17: RFC_FITS | K17: 3: Medium | L17: Confirm_Closed | M17: Add Substitute for Webcycle Readsoft | N17: SIE_S4P_RS Siemens S4P - Readsoft | Q17: =DATEDIF(E17,TODAY(),"d") -> 309 | R17: =IF($Q17>7,1,0) -> 1 | S17: =IF($Q17>30,1,0) -> 1
A18: 6000131438 | B18: INC42234456 | D18: 3003 | E18: 45701 | G18: Mario Beck (SRE DP PM EU / Z00109RY) | H18: Ramesh Itamsetti | I18: 45824 | J18: Ulrich Rauch | K18: 3: Medium | L18: Proposed Solution | M18: S4P 100 VIM - Fehlermeldung bei WF-Freigabe | N18: SIE_S4P_RS Siemens S4P - Readsoft | Q18: =DATEDIF(E18,TODAY(),"d") -> 306 | R18: =IF($Q18>7,1,0) -> 1 | S18: =IF($Q18>30,1,0) -> 1
A19: 6000131514 | D19: 7092 | E19: 45702 | G19: Ulrich Rauch (IT ECP ERP-CP ARC2 / Z00060NO) | H19: Ulrich Rauch / 81739 Muenchen | I19: 45723 | J19: SAP SOLUTION MANAGER S1A | K19: 3: Medium | L19: Confirm_Closed | M19: VIM: VIM Authorization issue in Exceptions App (mid-term solution) | N19: SIE_S4P_RS Siemens S4P - Readsoft | Q19: =DATEDIF(E19,I19,"d") -> 21 | R19: =IF($Q19>7,1,0) -> 1 | S19: =IF($Q19>30,1,0) -> 0
A20: 6000131715 | B20: INC42252236 | D20: 5975 | E20: 45705 | G20: Pavel Mego (GBS CEE P2P CZ AP 2 4 / Z001SCDJ) | H20: Ulrich Rauch / 81739 Muenchen | I20: 45713 | J20: RFC_FITS | K20: 4: Low | L20: Confirm_Closed | M20: duplicity check | N20: SIE_S4P_RS Siemens S4P - Readsoft | Q20: =DATEDIF(E20,TODAY(),"d") -> 302 | R20: =IF($Q20>7,1,0) -> 1 | S20: =IF($Q20>30,1,0) -> 1
A21: 6000132000 | B21: INC42270698 | D21: SRE | E21: 45707 | G21: Zdenek Cifka (GBS CEE P2P CZ AP 2 3 / Z003JPCS) | H21: Albert Galek | I21: 45735 | J21: RFC_FITS | K21: 3: Medium | L21: Confirm_Closed | M21: In VIM it is not possible to post the recurring documents, which contain multiple Profit Centers - VIM ID 3988 and 4340 | N21: SIE_S4P_RS Siemens S4P - Readsoft | Q21: =DATEDIF(E21,TODAY(),"d") -> 300 | R21: =IF($Q21>7,1,0) -> 1 | S21: =IF($Q21>30,1,0) -> 1
A22: 6000132651 | B22: INC42313692 | D22: 3003 | E22: 45714 | G22: Mario Beck (SRE DP PM EU / Z00109RY) | H22: Albert Galek | I22: 45723 | J22: RFC_FITS | K22: 4: Low | L22: Confirm_Closed | M22: S4P 100 VIM - #2777 can't be approved (new error message) | N22: SIE_S4P_RS Siemens S4P - Readsoft | Q22: =DATEDIF(E22,TODAY(),"d") -> 293 | R22: =IF($Q22>7,1,0) -> 1 | S22: =IF($Q22>30,1,0) -> 1
A23: 6000133013 | B23: INC42339428 | D23: 5975 | E23: 45719 | G23: Jitka Krnavkova (GBS CEE P2P CZ AP 2 4 / Z002HBHS) | H23: Ilona Splichalova | I23: 45734 | J23: RFC_FITS | K23: 4: Low | L23: Confirm_Closed | M23: Add user to ICFR group_READSOFT | N23: SIE_S4P_RS Siemens S4P - Readsoft | Q23: =DATEDIF(E23,TODAY(),"d") -> 288 | R23: =IF($Q23>7,1,0) -> 1 | S23: =IF($Q23>30,1,0) -> 1
A24: 6000133061 | B24: INC42342340 | D24: SRE | E24: 45719 | G24: Zdenek Cifka (GBS CEE P2P CZ AP 2 3 / Z003JPCS) | H24: Ilona Splichalova | I24: 45735 | J24: RFC_FITS | K24: 3: Medium | L24: Confirm_Closed | M24: VIM ID 1785 - approval workflow wasn't started but nevertheless is situated in VIM WP in My pending section | N24: SIE_S4P_RS Siemens S4P - Readsoft | Q24: =DATEDIF(E24,TODAY(),"d") -> 288 | R24: =IF($Q24>7,1,0) -> 1 | S24: =IF($Q24>30,1,0) -> 1
A25: 6000133063 | B25: INC42342645 | D25: 5220 | E25: 45719 | G25: Simona-Elena Kovar (CF R EEA PP PI / Z0046E1M) | H25: Ilona Splichalova | I25: 45778 | J25: RFC_FITS | K25: 4: Low | L25: Confirm_Closed | M25: GR posted, the payment block was removed in the background -> VIM workflow NOT completed | N25: SIE_S4P_RS Siemens S4P - Readsoft | Q25: =DATEDIF(E25,TODAY(),"d") -> 288 | R25: =IF($Q25>7,1,0) -> 1 | S25: =IF($Q25>30,1,0) -> 1
A26: 6000133075 | B26: INC42342669 | D26: 5220 | E26: 45719 | G26: Simona-Elena Kovar (CF R EEA PP PI / Z0046E1M) | H26: Albert Galek | I26: 45758 | J26: RFC_FITS | K26: 4: Low | L26: Confirm_Closed | M26: the document requires a technical approval although there is no price or quantity deviation | N26: SIE_S4P_RS Siemens S4P - Readsoft | Q26: =DATEDIF(E26,TODAY(),"d") -> 288 | R26: =IF($Q26>7,1,0) -> 1 | S26: =IF($Q26>30,1,0) -> 1
A27: 6000133085 | D27: 7092 | E27: 45719 | G27: Ulrich Rauch (IT ECP ERP-CP ARC2 / Z00060NO) | H27: Albert Galek | I27: 45731 | J27: SAP SOLUTION MANAGER S1A | K27: 3: Medium | L27: Confirm_Closed | M27: VIM: direct material PO: not able to choose non preferred approver | N27: SIE_S4P_RS Siemens S4P - Readsoft | Q27: =DATEDIF(E27,TODAY(),"d") -> 288 | R27: =IF($Q27>7,1,0) -> 1 | S27: =IF($Q27>30,1,0) -> 1
A28: 6000133086 | D28: 7092 | E28: 45719 | G28: Ulrich Rauch (IT ECP ERP-CP ARC2 / Z00060NO) | H28: Albert Galek | I28: 45773 | J28: SAP SOLUTION MANAGER S1A | K28: 3: Medium | L28: Confirm_Closed | M28: VIM ID 1785 and 5352 - approval workflow wasn't started but nevertheless is s | N28: SIE_S4P_RS Siemens S4P - Readsoft | Q28: =DATEDIF(E28,TODAY(),"d") -> 288 | R28: =IF($Q28>7,1,0) -> 1 | S28: =IF($Q28>30,1,0) -> 1
A29: 6000133087 | D29: 7092 | E29: 45719 | G29: Ulrich Rauch (IT ECP ERP-CP ARC2 / Z00060NO) | H29: Ilona Splichalova | I29: 45807 | J29: SAP SOLUTION MANAGER S1A | K29: 3: Medium | L29: Confirm_Closed | M29: VIM: different statuses in VIM Workplace and VIM Analytics | N29: SIE_S4P_RS Siemens S4P - Readsoft | Q29: =DATEDIF(E29,TODAY(),"d") -> 288 | R29: =IF($Q29>7,1,0) -> 1 | S29: =IF($Q29>30,1,0) -> 1
A30: 6000133442 | D30: 3003 | E30: 45722 | G30: Ilona Splichalova (DI IT ERP CZ FICO / Z002Z2VA) | H30: Ilona Splichalova | I30: 45786 | J30: SAP SOLUTION MANAGER S1A | K30: 3: Medium | L30: Confirm_Closed | M30: In VIM is not possible to cancel the invoice - DP 4288 | N30: SIE_S4P_RS Siemens S4P - Readsoft | Q30: =DATEDIF(E30,TODAY(),"d") -> 285 | R30: =IF($Q30>7,1,0) -> 1 | S30: =IF($Q30>30,1,0) -> 1
A31: 6000133644 | B31: INC42377517 | D31: 3014 | E31: 45723 | G31: Simon Kostovski (GBS CEE P2P CZ AP PE 2 / Z003DW1N) | H31: Albert Galek | I31: 45789 | J31: Ilona Splichalova | K31: 3: Medium | L31: In Process | M31: S4P Please adjust the VAT date to be identical with the invoice date for Company code 3014 | N31: SIE_S4P_RS Siemens S4P - Readsoft | Q31: =DATEDIF(E31,TODAY(),"d") -> 284 | R31: =IF($Q31>7,1,0) -> 1 | S31: =IF($Q31>30,1,0) -> 1
A32: 6000133647 | B32: INC42377569 | D32: 5975 | E32: 45723 | G32: Jan Binder (GBS CEE P2P CZ AP 2 2 / Z00435WC) | H32: Ilona Splichalova | I32: 45733 | J32: RFC_FITS | K32: 4: Low | L32: Confirm_Closed | M32: Receipt of invoices and posting in a different month/period. | N32: SIE_S4P_RS Siemens S4P - Readsoft | Q32: =DATEDIF(E32,TODAY(),"d") -> 284 | R32: =IF($Q32>7,1,0) -> 1 | S32: =IF($Q32>30,1,0) -> 1
A33: 6000133780 | B33: INC42386307 | D33: 3014 | E33: 45726 | G33: Andrei Vulpescu (DI MC GMC MF-EWN PU-BUZ FIN / Z00172BA) | H33: Albert Galek | I33: 45741 | J33: RFC_FITS | K33: 4: Low | L33: Confirm_Closed | M33: I cannot approve invoice release | N33: SIE_S4P_RS Siemens S4P - Readsoft | Q33: =DATEDIF(E33,TODAY(),"d") -> 281 | R33: =IF($Q33>7,1,0) -> 1 | S33: =IF($Q33>30,1,0) -> 1
A34: 6000133782 | B34: INC42386439 | D34: SRE | E34: 45726 | G34: Zdenek Cifka (GBS CEE P2P CZ AP 2 3 / Z003JPCS) | H34: Albert Galek | I34: 45735 | J34: RFC_FITS | K34: 3: Medium | L34: Confirm_Closed | M34: At VIM ID's 2977 and 1961 it's not possible to recall the approval workflow because they are situated in VIM WP in My co | N34: SIE_S4P_RS Siemens S4P - Readsoft | Q34: =DATEDIF(E34,TODAY(),"d") -> 281 | R34: =IF($Q34>7,1,0) -> 1 | S34: =IF($Q34>30,1,0) -> 1
A35: 6000133815 | B35: INC42387821 | D35: SRE | E35: 45726 | G35: Zdenek Cifka (GBS CEE P2P CZ AP 2 3 / Z003JPCS) | H35: Albert Galek | I35: 45748 | J35: RFC_FITS | K35: 3: Medium | L35: Confirm_Closed | M35: VIM ID 5033 - it's not possible to start the approval workflow manually for the specific person. | N35: SIE_S4P_RS Siemens S4P - Readsoft | Q35: =DATEDIF(E35,TODAY(),"d") -> 281 | R35: =IF($Q35>7,1,0) -> 1 | S35: =IF($Q35>30,1,0) -> 1
A36: 6000133897 | D36: 5975 | E36: 45727 | G36: Ilona Splichalova (DI IT ERP CZ FICO / Z002Z2VA) | H36: Albert Galek | I36: 45751 | J36: SAP SOLUTION MANAGER S1A | K36: 3: Medium | L36: Confirm_Closed | M36: VIM Table U-date Clarifications | N36: SIE_S4P_RS Siemens S4P - Readsoft | Q36: =DATEDIF(E36,TODAY(),"d") -> 280 | R36: =IF($Q36>7,1,0) -> 1 | S36: =IF($Q36>30,1,0) -> 1
A37: 6000134052 | B37: INC42401853 | D37: 3014 | E37: 45728 | G37: Ivana Tomisova (GBS CEE P2P CZ AP 3 2 / Z004PK7A) | H37: Mr. Silambarasan Vasu | I37: 45819 | K37: 4: Low | L37: Forwarded | M37: 3014 - ICC invoice not visible in VIM workplace | N37: MM - Materials Management | Q37: =DATEDIF(E37,TODAY(),"d") -> 279 | R37: =IF($Q37>7,1,0) -> 1 | S37: =IF($Q37>30,1,0) -> 1
A38: 6000134157 | B38: INC42406593 | D38: 5975 | E38: 45729 | G38: Pavel Mego (GBS CEE P2P CZ AP 2 4 / Z001SCDJ) | H38: Ilona Splichalova | I38: 45737 | J38: RFC_FITS | K38: 4: Low | L38: Confirm_Closed | M38: Stucked Webcycle | N38: SIE_S4P_RS Siemens S4P - Readsoft | Q38: =DATEDIF(E38,TODAY(),"d") -> 278 | R38: =IF($Q38>7,1,0) -> 1 | S38: =IF($Q38>30,1,0) -> 1
A39: 6000134167 | D39: 7092 | E39: 45729 | G39: Muskan Khanum Nagad (IT ECP ERP-CP / Z0053CPH) | H39: Albert Galek | I39: 45792 | J39: SAP SOLUTION MANAGER S1A | K39: 3: Medium | L39: Confirm_Closed | M39: Abap programming error in S4P | N39: SIE_S4P_RS Siemens S4P - Readsoft | Q39: =DATEDIF(E39,TODAY(),"d") -> 278 | R39: =IF($Q39>7,1,0) -> 1 | S39: =IF($Q39>30,1,0) -> 1
A40: 6000134304 | B40: INC42414880 | D40: 7011 | E40: 45729 | G40: Cosmin-Ovidiu Sarbu (DI MC GMC MF-EWN PU-BUZ FIN BC / Z0026A | H40: Ilona Splichalova | I40: 45782 | J40: RFC_FITS | K40: 4: Low | L40: Confirm_Closed | M40: Approval of invoices in VIM according to SAT | N40: SIE_S4P_RS Siemens S4P - Readsoft | Q40: =DATEDIF(E40,TODAY(),"d") -> 278 | R40: =IF($Q40>7,1,0) -> 1 | S40: =IF($Q40>30,1,0) -> 1
...

Sheet VIM-Incidents_W26(June26)
A1: ID | B1: FutureNow Ticket | C1: External ID | D1: ARE | E1: Created On | F1: Due by | G1: Reported By | H1: Message Processor | I1: Last Changed on | J1: Last Changed By | K1: Priority | L1: Status | M1: Description | N1: Support Team | O1: System ID | Q1: Open Days | R1: Open 7D+ | S1: Open 15D+ | T1: Open 30D+ | U1: Open 60D+
A2: 6000127070 | B2: INC41987224 | D2: 5975 | E2: 45663 | G2: Lenka Michalusova (GBS CEE P2P CZ AP 2 4 / Z002HBHR) | H2: Ulrich Rauch / 81739 Muenchen | I2: 45727 | J2: RFC_FITS | K2: 4: Low | L2: Confirm_Closed | M2: VIM- missing tax code | N2: SIE_S4P_RS Siemens S4P - Readsoft | Q2: =IF(OR(ISNUMBER(MATCH(L2,MasterData!$D$3:$D$18,0)),ISNUMBER(MATCH(L2,MasterData!$C$3:$C$18,0))), DATEDIF(E2,I2,"d"), DATEDIF(E2,TODAY(),"d")) -> 64 | R2: =IF($Q2>7,1,0) -> 1 | S2: =IF($Q2>15,1,0) -> 1 | T2: =IF($Q2>30,1,0) -> 1 | U2: =IF($Q2>60,1,0) -> 1
A3: 6000127209 | B3: INC41997245 | D3: 5975 | E3: 45664 | G3: Simon Kostovski (GBS CEE P2P CZ AP 3 2 / Z003DW1N) | H3: Albert Galek | I3: 45673 | J3: RFC_FITS | K3: 3: Medium | L3: Confirm_Closed | M3: INC41861079 not solved but it was closed | N3: SIE_S4P_RS Siemens S4P - Readsoft | Q3: =IF(OR(ISNUMBER(MATCH(L3,MasterData!$D$3:$D$18,0)),ISNUMBER(MATCH(L3,MasterData!$C$3:$C$18,0))), DATEDIF(E3,I3,"d"), DATEDIF(E3,TODAY(),"d")) -> 9 | R3: =IF($Q3>7,1,0) -> 1 | S3: =IF($Q3>15,1,0) -> 0 | T3: =IF($Q3>30,1,0) -> 0 | U3: =IF($Q3>60,1,0) -> 0
A4: 6000127632 | B4: INC42022656 | D4: 5975 | E4: 45667 | G4: Barbora Struskova (GBS CEE P2P CZ AP 2 4 / Z002HZ1U) | H4: Ilona Splichalova | I4: 45679 | J4: RFC_FITS | K4: 4: Low | L4: Confirm_Closed | M4: automatic text | N4: SIE_S4P_RS Siemens S4P - Readsoft | Q4: =IF(OR(ISNUMBER(MATCH(L4,MasterData!$D$3:$D$18,0)),ISNUMBER(MATCH(L4,MasterData!$C$3:$C$18,0))), DATEDIF(E4,I4,"d"), DATEDIF(E4,TODAY(),"d")) -> 12 | R4: =IF($Q4>7,1,0) -> 1 | S4: =IF($Q4>15,1,0) -> 0 | T4: =IF($Q4>30,1,0) -> 0 | U4: =IF($Q4>60,1,0) -> 0
A5: 6000128352 | D5: 3003 | E5: 45674 | G5: Ilona Splichalova (DI IT ERP CZ FICO / Z002Z2VA) | H5: Albert Galek | I5: 45688 | J5: SAP SOLUTION MANAGER S1A | K5: 3: Medium | L5: Confirm_Closed | M5: DP 2807 in S4P: please check the status | N5: SIE_S4P_RS Siemens S4P - Readsoft | Q5: =IF(OR(ISNUMBER(MATCH(L5,MasterData!$D$3:$D$18,0)),ISNUMBER(MATCH(L5,MasterData!$C$3:$C$18,0))), DATEDIF(E5,I5,"d"), DATEDIF(E5,TODAY(),"d")) -> 14 | R5: =IF($Q5>7,1,0) -> 1 | S5: =IF($Q5>15,1,0) -> 0 | T5: =IF($Q5>30,1,0) -> 0 | U5: =IF($Q5>60,1,0) -> 0
A6: 6000128500 | B6: INC42075263 | D6: 7092 | E6: 45677 | G6: Lena Osterhus (CE SEC TPC / Z001MA1B) | H6: Ilona Splichalova | I6: 45684 | J6: RFC_FITS | K6: 4: Low | L6: Confirm_Closed | M6: Falsche Emailadresse bei Readsoft/ WebCycle | N6: SIE_S4P_RS Siemens S4P - Readsoft | Q6: =IF(OR(ISNUMBER(MATCH(L6,MasterData!$D$3:$D$18,0)),ISNUMBER(MATCH(L6,MasterData!$C$3:$C$18,0))), DATEDIF(E6,I6,"d"), DATEDIF(E6,TODAY(),"d")) -> 7 | R6: =IF($Q6>7,1,0) -> 0 | S6: =IF($Q6>15,1,0) -> 0 | T6: =IF($Q6>30,1,0) -> 0 | U6: =IF($Q6>60,1,0) -> 0
A7: 6000128546 | B7: INC42077895 | D7: SRE | E7: 45677 | G7: Zdenek Cifka (GBS CEE P2P CZ AP 2 3 / Z003JPCS) | H7: Ilona Splichalova | I7: 45833 | J7: Ulrich Rauch | K7: 3: Medium | L7: Postponed | M7: VIM ID's 2391 and 2623 - after posting the payment block was'nt entered and approval workflow was'nt started | N7: SIE_S4P_RS Siemens S4P - Readsoft | Q7: =IF(OR(ISNUMBER(MATCH(L7,MasterData!$D$3:$D$18,0)),ISNUMBER(MATCH(L7,MasterData!$C$3:$C$18,0))), DATEDIF(E7,I7,"d"), DATEDIF(E7,TODAY(),"d")) -> 330 | R7: =IF($Q7>7,1,0) -> 1 | S7: =IF($Q7>15,1,0) -> 1 | T7: =IF($Q7>30,1,0) -> 1 | U7: =IF($Q7>60,1,0) -> 1
A8: 6000128759 | B8: INC42093959 | D8: 7092 | E8: 45679 | G8: Andreas Mengele (MAP DF&PCM PCM / Z001THRJ) | H8: Ilona Splichalova | I8: 45686 | J8: RFC_FITS | K8: 4: Low | L8: Confirm_Closed | M8: Umstellung der Rechte von Susanne Spiegl auf Philipp Rath | N8: SIE_S4P_RS Siemens S4P - Readsoft | Q8: =IF(OR(ISNUMBER(MATCH(L8,MasterData!$D$3:$D$18,0)),ISNUMBER(MATCH(L8,MasterData!$C$3:$C$18,0))), DATEDIF(E8,I8,"d"), DATEDIF(E8,TODAY(),"d")) -> 7 | R8: =IF($Q8>7,1,0) -> 0 | S8: =IF($Q8>15,1,0) -> 0 | T8: =IF($Q8>30,1,0) -> 0 | U8: =IF($Q8>60,1,0) -> 0
A9: 6000129022 | B9: INC42106952 | D9: 5975 | E9: 45680 | G9: Renata Staricna (GBS CEE P2P CZ AP 2 4 / Z0046K6B) | H9: Ilona Splichalova | I9: 45705 | J9: RFC_FITS | K9: 4: Low | L9: Confirm_Closed | M9: Reminder - automatic answers | N9: SIE_S4P_RS Siemens S4P - Readsoft | Q9: =IF(OR(ISNUMBER(MATCH(L9,MasterData!$D$3:$D$18,0)),ISNUMBER(MATCH(L9,MasterData!$C$3:$C$18,0))), DATEDIF(E9,I9,"d"), DATEDIF(E9,TODAY(),"d")) -> 25 | R9: =IF($Q9>7,1,0) -> 1 | S9: =IF($Q9>15,1,0) -> 1 | T9: =IF($Q9>30,1,0) -> 0 | U9: =IF($Q9>60,1,0) -> 0
A10: 6000129245 | B10: INC42120663 | D10: 7092 | E10: 45684 | G10: Veronika Andres (IT ECP FPS T&CS / Z0029JJZ) | H10: Ilona Splichalova | I10: 45691 | J10: RFC_FITS | K10: 4: Low | L10: Confirm_Closed | M10: WebCycle User locked | N10: SIE_S4P_RS Siemens S4P - Readsoft | Q10: =IF(OR(ISNUMBER(MATCH(L10,MasterData!$D$3:$D$18,0)),ISNUMBER(MATCH(L10,MasterData!$C$3:$C$18,0))), DATEDIF(E10,I10,"d"), DATEDIF(E10,TODAY(),"d")) -> 7 | R10: =IF($Q10>7,1,0) -> 0 | S10: =IF($Q10>15,1,0) -> 0 | T10: =IF($Q10>30,1,0) -> 0 | U10: =IF($Q10>60,1,0) -> 0
A11: 6000129304 | B11: INC42122188 | D11: SRE | E11: 45684 | G11: Tobias Moest (SRE FIN AR 2 / Z000F12V) | H11: Albert Galek | I11: 45693 | J11: RFC_FITS | K11: 4: Low | L11: Confirm_Closed | M11: S4P 100 - VIM: Vorgang aus Klärungs-WF nicht vorhanden | N11: SIE_S4P_RS Siemens S4P - Readsoft | Q11: =IF(OR(ISNUMBER(MATCH(L11,MasterData!$D$3:$D$18,0)),ISNUMBER(MATCH(L11,MasterData!$C$3:$C$18,0))), DATEDIF(E11,I11,"d"), DATEDIF(E11,TODAY(),"d")) -> 9 | R11: =IF($Q11>7,1,0) -> 1 | S11: =IF($Q11>15,1,0) -> 0 | T11: =IF($Q11>30,1,0) -> 0 | U11: =IF($Q11>60,1,0) -> 0
A12: 6000129653 | D12: 3003 | E12: 45686 | G12: Ilona Splichalova (DI IT ERP CZ FICO / Z002Z2VA) | H12: Ilona Splichalova | I12: 45782 | J12: SAP SOLUTION MANAGER S1A | K12: 3: Medium | L12: Confirm_Closed | M12: VIM 2756 und 2774 - Error by 3 step approval WF by Construction Invoices | N12: SIE_S4P_RS Siemens S4P - Readsoft | Q12: =IF(OR(ISNUMBER(MATCH(L12,MasterData!$D$3:$D$18,0)),ISNUMBER(MATCH(L12,MasterData!$C$3:$C$18,0))), DATEDIF(E12,I12,"d"), DATEDIF(E12,TODAY(),"d")) -> 96 | R12: =IF($Q12>7,1,0) -> 1 | S12: =IF($Q12>15,1,0) -> 1 | T12: =IF($Q12>30,1,0) -> 1 | U12: =IF($Q12>60,1,0) -> 1
A13: 6000129990 | B13: INC42154604 | D13: SRE | E13: 45688 | G13: Zdenek Cifka (GBS CEE P2P CZ AP 2 3 / Z003JPCS) | H13: Albert Galek | I13: 45699 | J13: RFC_FITS | K13: 3: Medium | L13: Confirm_Closed | M13: Is not possible to start the approval workflow for VIM ID 2515 | N13: SIE_S4P_RS Siemens S4P - Readsoft | Q13: =IF(OR(ISNUMBER(MATCH(L13,MasterData!$D$3:$D$18,0)),ISNUMBER(MATCH(L13,MasterData!$C$3:$C$18,0))), DATEDIF(E13,I13,"d"), DATEDIF(E13,TODAY(),"d")) -> 11 | R13: =IF($Q13>7,1,0) -> 1 | S13: =IF($Q13>15,1,0) -> 0 | T13: =IF($Q13>30,1,0) -> 0 | U13: =IF($Q13>60,1,0) -> 0
A14: 6000130122 | B14: INC42161605 | D14: 3014 | E14: 45691 | G14: Pompilia Bianca Trifa (DI MC GMC MF-EWN PU-BUZ FIN LOG 1-2 / | H14: Ulrich Rauch / 81739 Muenchen | I14: 45708 | J14: RFC_FITS | K14: 3: Medium | L14: Confirm_Closed | M14: S4P VIM - Invoices in Approval steps (direct materials) not visible to the approver | N14: SIE_S4P_RS Siemens S4P - Readsoft | Q14: =IF(OR(ISNUMBER(MATCH(L14,MasterData!$D$3:$D$18,0)),ISNUMBER(MATCH(L14,MasterData!$C$3:$C$18,0))), DATEDIF(E14,I14,"d"), DATEDIF(E14,TODAY(),"d")) -> 17 | R14: =IF($Q14>7,1,0) -> 1 | S14: =IF($Q14>15,1,0) -> 1 | T14: =IF($Q14>30,1,0) -> 0 | U14: =IF($Q14>60,1,0) -> 0
A15: 6000130131 | B15: INC42161726 | D15: 3014 | E15: 45691 | G15: Andreea Laura Boran (DI MC GMC MF-EWN PU-BUZ FIN LOG 1-2 / Z | H15: Ulrich Rauch / 81739 Muenchen | I15: 45708 | J15: RFC_FITS | K15: 3: Medium | L15: Confirm_Closed | M15: S4P - VIM error in invoice approval | N15: SIE_S4P_RS Siemens S4P - Readsoft | Q15: =IF(OR(ISNUMBER(MATCH(L15,MasterData!$D$3:$D$18,0)),ISNUMBER(MATCH(L15,MasterData!$C$3:$C$18,0))), DATEDIF(E15,I15,"d"), DATEDIF(E15,TODAY(),"d")) -> 17 | R15: =IF($Q15>7,1,0) -> 1 | S15: =IF($Q15>15,1,0) -> 1 | T15: =IF($Q15>30,1,0) -> 0 | U15: =IF($Q15>60,1,0) -> 0
A16: 6000130842 | B16: INC42203263 | D16: 3003 | E16: 45698 | G16: Helge Preiss (SRE DP PM EU / Z001WZ3K) | H16: Albert Galek | I16: 45831 | J16: RFC_FITS | K16: 3: Medium | L16: Confirm_Closed | M16: S4P VIM FIORI Approval Invoice Management Fehlermeldung | N16: SIE_S4P_RS Siemens S4P - Readsoft | Q16: =IF(OR(ISNUMBER(MATCH(L16,MasterData!$D$3:$D$18,0)),ISNUMBER(MATCH(L16,MasterData!$C$3:$C$18,0))), DATEDIF(E16,I16,"d"), DATEDIF(E16,TODAY(),"d")) -> 133 | R16: =IF($Q16>7,1,0) -> 1 | S16: =IF($Q16>15,1,0) -> 1 | T16: =IF($Q16>30,1,0) -> 1 | U16: =IF($Q16>60,1,0) -> 1
A17: 6000130889 | B17: INC42205466 | D17: 7092 | E17: 45698 | G17: Laura Hochwind (IT ECP FPS AP1 / Z003NVNW) | H17: Ulrich Rauch / 81739 Muenchen | I17: 45705 | J17: RFC_FITS | K17: 3: Medium | L17: Confirm_Closed | M17: Add Substitute for Webcycle Readsoft | N17: SIE_S4P_RS Siemens S4P - Readsoft | Q17: =IF(OR(ISNUMBER(MATCH(L17,MasterData!$D$3:$D$18,0)),ISNUMBER(MATCH(L17,MasterData!$C$3:$C$18,0))), DATEDIF(E17,I17,"d"), DATEDIF(E17,TODAY(),"d")) -> 7 | R17: =IF($Q17>7,1,0) -> 0 | S17: =IF($Q17>15,1,0) -> 0 | T17: =IF($Q17>30,1,0) -> 0 | U17: =IF($Q17>60,1,0) -> 0
A18: 6000131438 | B18: INC42234456 | D18: 3003 | E18: 45701 | G18: Mario Beck (SRE DP PM EU / Z00109RY) | H18: Ramesh Itamsetti | I18: 45831 | J18: RFC_FITS | K18: 3: Medium | L18: Confirm_Closed | M18: S4P 100 VIM - Fehlermeldung bei WF-Freigabe | N18: SIE_S4P_RS Siemens S4P - Readsoft | Q18: =IF(OR(ISNUMBER(MATCH(L18,MasterData!$D$3:$D$18,0)),ISNUMBER(MATCH(L18,MasterData!$C$3:$C$18,0))), DATEDIF(E18,I18,"d"), DATEDIF(E18,TODAY(),"d")) -> 130 | R18: =IF($Q18>7,1,0) -> 1 | S18: =IF($Q18>15,1,0) -> 1 | T18: =IF($Q18>30,1,0) -> 1 | U18: =IF($Q18>60,1,0) -> 1
A19: 6000131514 | D19: 7092 | E19: 45702 | G19: Ulrich Rauch (IT ECP ERP-CP ARC2 / Z00060NO) | H19: Ulrich Rauch / 81739 Muenchen | I19: 45723 | J19: SAP SOLUTION MANAGER S1A | K19: 3: Medium | L19: Confirm_Closed | M19: VIM: VIM Authorization issue in Exceptions App (mid-term solution) | N19: SIE_S4P_RS Siemens S4P - Readsoft | Q19: =IF(OR(ISNUMBER(MATCH(L19,MasterData!$D$3:$D$18,0)),ISNUMBER(MATCH(L19,MasterData!$C$3:$C$18,0))), DATEDIF(E19,I19,"d"), DATEDIF(E19,TODAY(),"d")) -> 21 | R19: =IF($Q19>7,1,0) -> 1 | S19: =IF($Q19>15,1,0) -> 1 | T19: =IF($Q19>30,1,0) -> 0 | U19: =IF($Q19>60,1,0) -> 0
A20: 6000131715 | B20: INC42252236 | D20: 5975 | E20: 45705 | G20: Pavel Mego (GBS CEE P2P CZ AP 2 4 / Z001SCDJ) | H20: Ulrich Rauch / 81739 Muenchen | I20: 45713 | J20: RFC_FITS | K20: 4: Low | L20: Confirm_Closed | M20: duplicity check | N20: SIE_S4P_RS Siemens S4P - Readsoft | Q20: =IF(OR(ISNUMBER(MATCH(L20,MasterData!$D$3:$D$18,0)),ISNUMBER(MATCH(L20,MasterData!$C$3:$C$18,0))), DATEDIF(E20,I20,"d"), DATEDIF(E20,TODAY(),"d")) -> 8 | R20: =IF($Q20>7,1,0) -> 1 | S20: =IF($Q20>15,1,0) -> 0 | T20: =IF($Q20>30,1,0) -> 0 | U20: =IF($Q20>60,1,0) -> 0
A21: 6000132000 | B21: INC42270698 | D21: SRE | E21: 45707 | G21: Zdenek Cifka (GBS CEE P2P CZ AP 2 3 / Z003JPCS) | H21: Albert Galek | I21: 45735 | J21: RFC_FITS | K21: 3: Medium | L21: Confirm_Closed | M21: In VIM it is not possible to post the recurring documents, which contain multiple Profit Centers - VIM ID 3988 and 4340 | N21: SIE_S4P_RS Siemens S4P - Readsoft | Q21: =IF(OR(ISNUMBER(MATCH(L21,MasterData!$D$3:$D$18,0)),ISNUMBER(MATCH(L21,MasterData!$C$3:$C$18,0))), DATEDIF(E21,I21,"d"), DATEDIF(E21,TODAY(),"d")) -> 28 | R21: =IF($Q21>7,1,0) -> 1 | S21: =IF($Q21>15,1,0) -> 1 | T21: =IF($Q21>30,1,0) -> 0 | U21: =IF($Q21>60,1,0) -> 0
A22: 6000132651 | B22: INC42313692 | D22: 3003 | E22: 45714 | G22: Mario Beck (SRE DP PM EU / Z00109RY) | H22: Albert Galek | I22: 45723 | J22: RFC_FITS | K22: 4: Low | L22: Confirm_Closed | M22: S4P 100 VIM - #2777 can't be approved (new error message) | N22: SIE_S4P_RS Siemens S4P - Readsoft | Q22: =IF(OR(ISNUMBER(MATCH(L22,MasterData!$D$3:$D$18,0)),ISNUMBER(MATCH(L22,MasterData!$C$3:$C$18,0))), DATEDIF(E22,I22,"d"), DATEDIF(E22,TODAY(),"d")) -> 9 | R22: =IF($Q22>7,1,0) -> 1 | S22: =IF($Q22>15,1,0) -> 0 | T22: =IF($Q22>30,1,0) -> 0 | U22: =IF($Q22>60,1,0) -> 0
A23: 6000133013 | B23: INC42339428 | D23: 5975 | E23: 45719 | G23: Jitka Krnavkova (GBS CEE P2P CZ AP 2 4 / Z002HBHS) | H23: Ilona Splichalova | I23: 45734 | J23: RFC_FITS | K23: 4: Low | L23: Confirm_Closed | M23: Add user to ICFR group_READSOFT | N23: SIE_S4P_RS Siemens S4P - Readsoft | Q23: =IF(OR(ISNUMBER(MATCH(L23,MasterData!$D$3:$D$18,0)),ISNUMBER(MATCH(L23,MasterData!$C$3:$C$18,0))), DATEDIF(E23,I23,"d"), DATEDIF(E23,TODAY(),"d")) -> 15 | R23: =IF($Q23>7,1,0) -> 1 | S23: =IF($Q23>15,1,0) -> 0 | T23: =IF($Q23>30,1,0) -> 0 | U23: =IF($Q23>60,1,0) -> 0
A24: 6000133061 | B24: INC42342340 | D24: SRE | E24: 45719 | G24: Zdenek Cifka (GBS CEE P2P CZ AP 2 3 / Z003JPCS) | H24: Ilona Splichalova | I24: 45735 | J24: RFC_FITS | K24: 3: Medium | L24: Confirm_Closed | M24: VIM ID 1785 - approval workflow wasn't started but nevertheless is situated in VIM WP in My pending section | N24: SIE_S4P_RS Siemens S4P - Readsoft | Q24: =IF(OR(ISNUMBER(MATCH(L24,MasterData!$D$3:$D$18,0)),ISNUMBER(MATCH(L24,MasterData!$C$3:$C$18,0))), DATEDIF(E24,I24,"d"), DATEDIF(E24,TODAY(),"d")) -> 16 | R24: =IF($Q24>7,1,0) -> 1 | S24: =IF($Q24>15,1,0) -> 1 | T24: =IF($Q24>30,1,0) -> 0 | U24: =IF($Q24>60,1,0) -> 0
A25: 6000133063 | B25: INC42342645 | D25: 5220 | E25: 45719 | G25: Simona-Elena Kovar (CF R EEA PP PI / Z0046E1M) | H25: Ilona Splichalova | I25: 45778 | J25: RFC_FITS | K25: 4: Low | L25: Confirm_Closed | M25: GR posted, the payment block was removed in the background -> VIM workflow NOT completed | N25: SIE_S4P_RS Siemens S4P - Readsoft | Q25: =IF(OR(ISNUMBER(MATCH(L25,MasterData!$D$3:$D$18,0)),ISNUMBER(MATCH(L25,MasterData!$C$3:$C$18,0))), DATEDIF(E25,I25,"d"), DATEDIF(E25,TODAY(),"d")) -> 59 | R25: =IF($Q25>7,1,0) -> 1 | S25: =IF($Q25>15,1,0) -> 1 | T25: =IF($Q25>30,1,0) -> 1 | U25: =IF($Q25>60,1,0) -> 0
